2022-01-13 14:27:54,491 55532 news_content_collection ERROR Exception in getting data from url speedtalk.com/forum/viewtopic.php?t=51650
Traceback (most recent call last):
  File "D:\Programs\FakeNewsNet\code\news_content_collection.py", line 25, in crawl_link_article
    article.parse()
  File "C:\Users\user\AppData\Local\Programs\Python\Python38\lib\site-packages\newspaper\article.py", line 191, in parse
    self.throw_if_not_downloaded_verbose()
  File "C:\Users\user\AppData\Local\Programs\Python\Python38\lib\site-packages\newspaper\article.py", line 531, in throw_if_not_downloaded_verbose
    raise ArticleException('Article `download()` failed with %s on URL %s' %
newspaper.article.ArticleException: Article `download()` failed with HTTPConnectionPool(host='speedtalk.com', port=80): Max retries exceeded with url: /forum/viewtopic.php?t=51650 (Caused by ConnectTimeoutError(<urllib3.connection.HTTPConnection object at 0x000002182B1B0130>, 'Connection to speedtalk.com timed out. (connect timeout=7)')) on URL http://speedtalk.com/forum/viewtopic.php?t=51650
2022-01-13 14:28:01,499 55532 news_content_collection ERROR Exception in getting data from url speedtalk.com/forum/viewtopic.php?t=51650
Traceback (most recent call last):
  File "C:\Users\user\AppData\Local\Programs\Python\Python38\lib\site-packages\urllib3\util\connection.py", line 70, in create_connection
    sock.connect(sa)
socket.timeout: timed out

During handling of the above exception, another exception occurred:

Traceback (most recent call last):
  File "D:\Programs\FakeNewsNet\code\news_content_collection.py", line 34, in crawl_link_article
    article.download()
  File "C:\Users\user\AppData\Local\Programs\Python\Python38\lib\site-packages\newspaper\article.py", line 170, in download
    html = network.get_html_2XX_only(self.url, self.config)
  File "C:\Users\user\AppData\Local\Programs\Python\Python38\lib\site-packages\newspaper\network.py", line 62, in get_html_2XX_only
    response = requests.get(
  File "C:\Users\user\AppData\Local\Programs\Python\Python38\lib\site-packages\requests\api.py", line 75, in get
    return request('get', url, params=params, **kwargs)
  File "C:\Users\user\AppData\Local\Programs\Python\Python38\lib\site-packages\requests\api.py", line 60, in request
    return session.request(method=method, url=url, **kwargs)
  File "C:\Users\user\AppData\Local\Programs\Python\Python38\lib\site-packages\requests\sessions.py", line 533, in request
    resp = self.send(prep, **send_kwargs)
  File "C:\Users\user\AppData\Local\Programs\Python\Python38\lib\site-packages\requests\sessions.py", line 646, in send
    r = adapter.send(request, **kwargs)
  File "C:\Users\user\AppData\Local\Programs\Python\Python38\lib\site-packages\requests\adapters.py", line 439, in send
    resp = conn.urlopen(
  File "C:\Users\user\AppData\Local\Programs\Python\Python38\lib\site-packages\urllib3\connectionpool.py", line 597, in urlopen
    httplib_response = self._make_request(conn, method, url,
  File "C:\Users\user\AppData\Local\Programs\Python\Python38\lib\site-packages\urllib3\connectionpool.py", line 343, in _make_request
    self._validate_conn(conn)
  File "C:\Users\user\AppData\Local\Programs\Python\Python38\lib\site-packages\urllib3\connectionpool.py", line 839, in _validate_conn
    conn.connect()
  File "C:\Users\user\AppData\Local\Programs\Python\Python38\lib\site-packages\urllib3\connection.py", line 301, in connect
    conn = self._new_conn()
  File "C:\Users\user\AppData\Local\Programs\Python\Python38\lib\site-packages\urllib3\connection.py", line 158, in _new_conn
    conn = connection.create_connection(
  File "C:\Users\user\AppData\Local\Programs\Python\Python38\lib\site-packages\urllib3\util\connection.py", line 70, in create_connection
    sock.connect(sa)
KeyboardInterrupt
2022-01-13 14:28:04,993 55532 news_content_collection ERROR Exception in getting data from url politics2020.info/index.php/2018/03/13/court-orders-obama-to-pay-400-million-in-restitution/
Traceback (most recent call last):
  File "D:\Programs\FakeNewsNet\code\news_content_collection.py", line 25, in crawl_link_article
    article.parse()
  File "C:\Users\user\AppData\Local\Programs\Python\Python38\lib\site-packages\newspaper\article.py", line 191, in parse
    self.throw_if_not_downloaded_verbose()
  File "C:\Users\user\AppData\Local\Programs\Python\Python38\lib\site-packages\newspaper\article.py", line 531, in throw_if_not_downloaded_verbose
    raise ArticleException('Article `download()` failed with %s on URL %s' %
newspaper.article.ArticleException: Article `download()` failed with HTTPConnectionPool(host='politics2020.info', port=80): Max retries exceeded with url: /index.php/2018/03/13/court-orders-obama-to-pay-400-million-in-restitution/ (Caused by NewConnectionError('<urllib3.connection.HTTPConnection object at 0x000002182AB45040>: Failed to establish a new connection: [Errno 11001] getaddrinfo failed')) on URL http://politics2020.info/index.php/2018/03/13/court-orders-obama-to-pay-400-million-in-restitution/
2022-01-13 14:28:07,003 55532 news_content_collection ERROR Exception in getting data from url politics2020.info/index.php/2018/03/13/court-orders-obama-to-pay-400-million-in-restitution/
Traceback (most recent call last):
  File "D:\Programs\FakeNewsNet\code\news_content_collection.py", line 36, in crawl_link_article
    article.parse()
  File "C:\Users\user\AppData\Local\Programs\Python\Python38\lib\site-packages\newspaper\article.py", line 191, in parse
    self.throw_if_not_downloaded_verbose()
  File "C:\Users\user\AppData\Local\Programs\Python\Python38\lib\site-packages\newspaper\article.py", line 531, in throw_if_not_downloaded_verbose
    raise ArticleException('Article `download()` failed with %s on URL %s' %
newspaper.article.ArticleException: Article `download()` failed with HTTPSConnectionPool(host='politics2020.info', port=443): Max retries exceeded with url: /index.php/2018/03/13/court-orders-obama-to-pay-400-million-in-restitution/ (Caused by NewConnectionError('<urllib3.connection.VerifiedHTTPSConnection object at 0x000002182B1B0D30>: Failed to establish a new connection: [Errno 11001] getaddrinfo failed')) on URL https://politics2020.info/index.php/2018/03/13/court-orders-obama-to-pay-400-million-in-restitution/
2022-01-13 14:28:29,118 55532 __init__ DEBUG Building prefix dict from C:\Users\user\AppData\Local\Programs\Python\Python38\lib\site-packages\jieba\dict.txt ...
2022-01-13 14:28:29,723 55532 __init__ DEBUG Dumping model to file cache C:\Users\user\AppData\Local\Temp\jieba.cache
2022-01-13 14:28:30,031 55532 __init__ DEBUG Loading model cost 0.9122483730316162 seconds.
2022-01-13 14:28:30,031 55532 __init__ DEBUG Prefix dict has been built succesfully.
2022-01-13 14:28:46,129 55532 news_content_collection ERROR Exception in getting data from url http://yournewswire.com/youngest-leader-george-soros/
Traceback (most recent call last):
  File "D:\Programs\FakeNewsNet\code\news_content_collection.py", line 49, in crawl_link_article
    article.parse()
  File "C:\Users\user\AppData\Local\Programs\Python\Python38\lib\site-packages\newspaper\article.py", line 191, in parse
    self.throw_if_not_downloaded_verbose()
  File "C:\Users\user\AppData\Local\Programs\Python\Python38\lib\site-packages\newspaper\article.py", line 531, in throw_if_not_downloaded_verbose
    raise ArticleException('Article `download()` failed with %s on URL %s' %
newspaper.article.ArticleException: Article `download()` failed with 404 Client Error: Not Found for url: https://yournewswire.com/youngest-leader-george-soros/ on URL http://yournewswire.com/youngest-leader-george-soros/
2022-01-13 14:28:47,956 55532 news_content_collection ERROR Exception in getting data from url https://web.archive.org/web/20171021234144/http://yournewswire.com/youngest-leader-george-soros/
Traceback (most recent call last):
  File "D:\Programs\FakeNewsNet\code\news_content_collection.py", line 48, in crawl_link_article
    time.sleep(2)
KeyboardInterrupt
2022-01-13 14:28:48,636 55532 news_content_collection ERROR Exception in getting data from url https://web.archive.org/web/20170731052757/http://politicspaper.com:80/breaking/breaking-hillary-clinton-third-heart-attack-docs-says-wont-survive/
Traceback (most recent call last):
  File "C:\Users\user\AppData\Local\Programs\Python\Python38\lib\site-packages\urllib3\connectionpool.py", line 377, in _make_request
    httplib_response = conn.getresponse(buffering=True)
TypeError: getresponse() got an unexpected keyword argument 'buffering'

During handling of the above exception, another exception occurred:

Traceback (most recent call last):
  File "D:\Programs\FakeNewsNet\code\news_content_collection.py", line 47, in crawl_link_article
    article.download()
  File "C:\Users\user\AppData\Local\Programs\Python\Python38\lib\site-packages\newspaper\article.py", line 170, in download
    html = network.get_html_2XX_only(self.url, self.config)
  File "C:\Users\user\AppData\Local\Programs\Python\Python38\lib\site-packages\newspaper\network.py", line 62, in get_html_2XX_only
    response = requests.get(
  File "C:\Users\user\AppData\Local\Programs\Python\Python38\lib\site-packages\requests\api.py", line 75, in get
    return request('get', url, params=params, **kwargs)
  File "C:\Users\user\AppData\Local\Programs\Python\Python38\lib\site-packages\requests\api.py", line 60, in request
    return session.request(method=method, url=url, **kwargs)
  File "C:\Users\user\AppData\Local\Programs\Python\Python38\lib\site-packages\requests\sessions.py", line 533, in request
    resp = self.send(prep, **send_kwargs)
  File "C:\Users\user\AppData\Local\Programs\Python\Python38\lib\site-packages\requests\sessions.py", line 646, in send
    r = adapter.send(request, **kwargs)
  File "C:\Users\user\AppData\Local\Programs\Python\Python38\lib\site-packages\requests\adapters.py", line 439, in send
    resp = conn.urlopen(
  File "C:\Users\user\AppData\Local\Programs\Python\Python38\lib\site-packages\urllib3\connectionpool.py", line 597, in urlopen
    httplib_response = self._make_request(conn, method, url,
  File "C:\Users\user\AppData\Local\Programs\Python\Python38\lib\site-packages\urllib3\connectionpool.py", line 380, in _make_request
    httplib_response = conn.getresponse()
  File "C:\Users\user\AppData\Local\Programs\Python\Python38\lib\http\client.py", line 1347, in getresponse
    response.begin()
  File "C:\Users\user\AppData\Local\Programs\Python\Python38\lib\http\client.py", line 307, in begin
    version, status, reason = self._read_status()
  File "C:\Users\user\AppData\Local\Programs\Python\Python38\lib\http\client.py", line 268, in _read_status
    line = str(self.fp.readline(_MAXLINE + 1), "iso-8859-1")
  File "C:\Users\user\AppData\Local\Programs\Python\Python38\lib\socket.py", line 669, in readinto
    return self._sock.recv_into(b)
  File "C:\Users\user\AppData\Local\Programs\Python\Python38\lib\ssl.py", line 1241, in recv_into
    return self.read(nbytes, buffer)
  File "C:\Users\user\AppData\Local\Programs\Python\Python38\lib\ssl.py", line 1099, in read
    return self._sslobj.read(len, buffer)
KeyboardInterrupt
